<mujoco><asset><mesh name="tooth_plate_mesh" file="tooth_mesh.obj" /></asset><worldbody><geom type="plane" pos="-1 0 0" quat="0.707 0 0.707 0" size="10 10 10" rgba="1 1 1 1" /><body name="rack" pos="0 0 0"><joint name="rack_slider" type="slide" axis="0 1 0" range="-2 2" frictionloss="0.5" solimpfriction="0.95 0.9999 0.001 0.1 2" solreffriction="0.000075 0.030" /><geom type="sphere" size="0.000015" pos="0.0 3.0000000000000004e-08 -4.9e-06" rgba="1 0.3 0.3 1" mass="0.00041269841269841274" contype="1" conaffinity="1" /><geom type="sphere" size="0.000015" pos="0.0 1.5e-06 0.0" rgba="1 0.3 0.3 1" mass="0.00041269841269841274" contype="1" conaffinity="1" /><geom type="sphere" size="0.000015" pos="0.0 0.00017984541479043915 0.00049" rgba="1 0.3 0.3 1" mass="0.00041269841269841274" contype="1" conaffinity="1" /><geom type="sphere" size="0.000015" pos="0.0 0.0001828454147904391 0.00049" rgba="1 0.3 0.3 1" mass="0.00041269841269841274" contype="1" conaffinity="1" /><geom type="sphere" size="0.000015" pos="0.0 0.0003611908295808783 0.0" rgba="1 0.3 0.3 1" mass="0.00041269841269841274" contype="1" conaffinity="1" /><geom type="sphere" size="0.000015" pos="0.0 0.0003626608295808783 -4.9e-06" rgba="1 0.3 0.3 1" mass="0.00041269841269841274" contype="1" conaffinity="1" /><geom type="sphere" size="0.000015" pos="0.0 -0.003626878295808783 -4.9e-06" rgba="1 0.3 0.3 1" mass="0.00041269841269841274" contype="1" conaffinity="1" /><geom type="sphere" size="0.000015" pos="0.0 -0.0036254082958087825 0.0" rgba="1 0.3 0.3 1" mass="0.00041269841269841274" contype="1" conaffinity="1" /><geom type="sphere" size="0.000015" pos="0.0 -0.0034470628810183437 0.00049" rgba="1 0.3 0.3 1" mass="0.00041269841269841274" contype="1" conaffinity="1" /><geom type="sphere" size="0.000015" pos="0.0 -0.0034440628810183437 0.00049" rgba="1 0.3 0.3 1" mass="0.00041269841269841274" contype="1" conaffinity="1" /><geom type="sphere" size="0.000015" pos="0.0 -0.0032657174662279044 0.0" rgba="1 0.3 0.3 1" mass="0.00041269841269841274" contype="1" conaffinity="1" /><geom type="sphere" size="0.000015" pos="0.0 -0.0032642474662279044 -4.9e-06" rgba="1 0.3 0.3 1" mass="0.00041269841269841274" contype="1" conaffinity="1" /><geom type="sphere" size="0.000015" pos="0.0 -0.0032641874662279044 -4.9e-06" rgba="1 0.3 0.3 1" mass="0.00041269841269841274" contype="1" conaffinity="1" /><geom type="sphere" size="0.000015" pos="0.0 -0.003262717466227904 0.0" rgba="1 0.3 0.3 1" mass="0.00041269841269841274" contype="1" conaffinity="1" /><geom type="sphere" size="0.000015" pos="0.0 -0.003084372051437465 0.00049" rgba="1 0.3 0.3 1" mass="0.00041269841269841274" contype="1" conaffinity="1" /><geom type="sphere" size="0.000015" pos="0.0 -0.003081372051437465 0.00049" rgba="1 0.3 0.3 1" mass="0.00041269841269841274" contype="1" conaffinity="1" /><geom type="sphere" size="0.000015" pos="0.0 -0.002903026636647026 0.0" rgba="1 0.3 0.3 1" mass="0.00041269841269841274" contype="1" conaffinity="1" /><geom type="sphere" size="0.000015" pos="0.0 -0.002901556636647026 -4.9e-06" rgba="1 0.3 0.3 1" mass="0.00041269841269841274" contype="1" conaffinity="1" /><geom type="sphere" size="0.000015" pos="0.0 -0.0029014966366470263 -4.9e-06" rgba="1 0.3 0.3 1" mass="0.00041269841269841274" contype="1" conaffinity="1" /><geom type="sphere" size="0.000015" pos="0.0 -0.002900026636647026 0.0" rgba="1 0.3 0.3 1" mass="0.00041269841269841274" contype="1" conaffinity="1" /><geom type="sphere" size="0.000015" pos="0.0 -0.002721681221856587 0.00049" rgba="1 0.3 0.3 1" mass="0.00041269841269841274" contype="1" conaffinity="1" /><geom type="sphere" size="0.000015" pos="0.0 -0.002718681221856587 0.00049" rgba="1 0.3 0.3 1" mass="0.00041269841269841274" contype="1" conaffinity="1" /><geom type="sphere" size="0.000015" pos="0.0 -0.0025403358070661478 0.0" rgba="1 0.3 0.3 1" mass="0.00041269841269841274" contype="1" conaffinity="1" /><geom type="sphere" size="0.000015" pos="0.0 -0.002538865807066148 -4.9e-06" rgba="1 0.3 0.3 1" mass="0.00041269841269841274" contype="1" conaffinity="1" /><geom type="sphere" size="0.000015" pos="0.0 -0.002538805807066148 -4.9e-06" rgba="1 0.3 0.3 1" mass="0.00041269841269841274" contype="1" conaffinity="1" /><geom type="sphere" size="0.000015" pos="0.0 -0.002537335807066148 0.0" rgba="1 0.3 0.3 1" mass="0.00041269841269841274" contype="1" conaffinity="1" /><geom type="sphere" size="0.000015" pos="0.0 -0.002358990392275709 0.00049" rgba="1 0.3 0.3 1" mass="0.00041269841269841274" contype="1" conaffinity="1" /><geom type="sphere" size="0.000015" pos="0.0 -0.002355990392275709 0.00049" rgba="1 0.3 0.3 1" mass="0.00041269841269841274" contype="1" conaffinity="1" /><geom type="sphere" size="0.000015" pos="0.0 -0.0021776449774852697 0.0" rgba="1 0.3 0.3 1" mass="0.00041269841269841274" contype="1" conaffinity="1" /><geom type="sphere" size="0.000015" pos="0.0 -0.0021761749774852697 -4.9e-06" rgba="1 0.3 0.3 1" mass="0.00041269841269841274" contype="1" conaffinity="1" /><geom type="sphere" size="0.000015" pos="0.0 -0.0021761149774852696 -4.9e-06" rgba="1 0.3 0.3 1" mass="0.00041269841269841274" contype="1" conaffinity="1" /><geom type="sphere" size="0.000015" pos="0.0 -0.0021746449774852693 0.0" rgba="1 0.3 0.3 1" mass="0.00041269841269841274" contype="1" conaffinity="1" /><geom type="sphere" size="0.000015" pos="0.0 -0.0019962995626948304 0.00049" rgba="1 0.3 0.3 1" mass="0.00041269841269841274" contype="1" conaffinity="1" /><geom type="sphere" size="0.000015" pos="0.0 -0.0019932995626948304 0.00049" rgba="1 0.3 0.3 1" mass="0.00041269841269841274" contype="1" conaffinity="1" /><geom type="sphere" size="0.000015" pos="0.0 -0.0018149541479043911 0.0" rgba="1 0.3 0.3 1" mass="0.00041269841269841274" contype="1" conaffinity="1" /><geom type="sphere" size="0.000015" pos="0.0 -0.0018134841479043912 -4.9e-06" rgba="1 0.3 0.3 1" mass="0.00041269841269841274" contype="1" conaffinity="1" /><geom type="sphere" size="0.000015" pos="0.0 -0.0018134241479043913 -4.9e-06" rgba="1 0.3 0.3 1" mass="0.00041269841269841274" contype="1" conaffinity="1" /><geom type="sphere" size="0.000015" pos="0.0 -0.0018119541479043914 0.0" rgba="1 0.3 0.3 1" mass="0.00041269841269841274" contype="1" conaffinity="1" /><geom type="sphere" size="0.000015" pos="0.0 -0.0016336087331139523 0.00049" rgba="1 0.3 0.3 1" mass="0.00041269841269841274" contype="1" conaffinity="1" /><geom type="sphere" size="0.000015" pos="0.0 -0.0016306087331139523 0.00049" rgba="1 0.3 0.3 1" mass="0.00041269841269841274" contype="1" conaffinity="1" /><geom type="sphere" size="0.000015" pos="0.0 -0.001452263318323513 0.0" rgba="1 0.3 0.3 1" mass="0.00041269841269841274" contype="1" conaffinity="1" /><geom type="sphere" size="0.000015" pos="0.0 -0.001450793318323513 -4.9e-06" rgba="1 0.3 0.3 1" mass="0.00041269841269841274" contype="1" conaffinity="1" /><geom type="sphere" size="0.000015" pos="0.0 -0.001450733318323513 -4.9e-06" rgba="1 0.3 0.3 1" mass="0.00041269841269841274" contype="1" conaffinity="1" /><geom type="sphere" size="0.000015" pos="0.0 -0.001449263318323513 0.0" rgba="1 0.3 0.3 1" mass="0.00041269841269841274" contype="1" conaffinity="1" /><geom type="sphere" size="0.000015" pos="0.0 -0.001270917903533074 0.00049" rgba="1 0.3 0.3 1" mass="0.00041269841269841274" contype="1" conaffinity="1" /><geom type="sphere" size="0.000015" pos="0.0 -0.001267917903533074 0.00049" rgba="1 0.3 0.3 1" mass="0.00041269841269841274" contype="1" conaffinity="1" /><geom type="sphere" size="0.000015" pos="0.0 -0.0010895724887426347 0.0" rgba="1 0.3 0.3 1" mass="0.00041269841269841274" contype="1" conaffinity="1" /><geom type="sphere" size="0.000015" pos="0.0 -0.0010881024887426348 -4.9e-06" rgba="1 0.3 0.3 1" mass="0.00041269841269841274" contype="1" conaffinity="1" /><geom type="sphere" size="0.000015" pos="0.0 -0.0010880424887426347 -4.9e-06" rgba="1 0.3 0.3 1" mass="0.00041269841269841274" contype="1" conaffinity="1" /><geom type="sphere" size="0.000015" pos="0.0 -0.0010865724887426347 0.0" rgba="1 0.3 0.3 1" mass="0.00041269841269841274" contype="1" conaffinity="1" /><geom type="sphere" size="0.000015" pos="0.0 -0.0009082270739521956 0.00049" rgba="1 0.3 0.3 1" mass="0.00041269841269841274" contype="1" conaffinity="1" /><geom type="sphere" size="0.000015" pos="0.0 -0.0009052270739521956 0.00049" rgba="1 0.3 0.3 1" mass="0.00041269841269841274" contype="1" conaffinity="1" /><geom type="sphere" size="0.000015" pos="0.0 -0.0007268816591617564 0.0" rgba="1 0.3 0.3 1" mass="0.00041269841269841274" contype="1" conaffinity="1" /><geom type="sphere" size="0.000015" pos="0.0 -0.0007254116591617565 -4.9e-06" rgba="1 0.3 0.3 1" mass="0.00041269841269841274" contype="1" conaffinity="1" /><geom type="sphere" size="0.000015" pos="0.0 -0.0007253516591617565 -4.9e-06" rgba="1 0.3 0.3 1" mass="0.00041269841269841274" contype="1" conaffinity="1" /><geom type="sphere" size="0.000015" pos="0.0 -0.0007238816591617565 0.0" rgba="1 0.3 0.3 1" mass="0.00041269841269841274" contype="1" conaffinity="1" /><geom type="sphere" size="0.000015" pos="0.0 -0.0005455362443713173 0.00049" rgba="1 0.3 0.3 1" mass="0.00041269841269841274" contype="1" conaffinity="1" /><geom type="sphere" size="0.000015" pos="0.0 -0.0005425362443713174 0.00049" rgba="1 0.3 0.3 1" mass="0.00041269841269841274" contype="1" conaffinity="1" /><geom type="sphere" size="0.000015" pos="0.0 -0.00036419082958087824 0.0" rgba="1 0.3 0.3 1" mass="0.00041269841269841274" contype="1" conaffinity="1" /><geom type="sphere" size="0.000015" pos="0.0 -0.00036272082958087825 -4.9e-06" rgba="1 0.3 0.3 1" mass="0.00041269841269841274" contype="1" conaffinity="1" /><geom type="sphere" size="0.000015" pos="0.0 -0.0003626608295808783 -4.9e-06" rgba="1 0.3 0.3 1" mass="0.00041269841269841274" contype="1" conaffinity="1" /><geom type="sphere" size="0.000015" pos="0.0 -0.0003611908295808783 0.0" rgba="1 0.3 0.3 1" mass="0.00041269841269841274" contype="1" conaffinity="1" /><geom type="sphere" size="0.000015" pos="0.0 -0.0001828454147904391 0.00049" rgba="1 0.3 0.3 1" mass="0.00041269841269841274" contype="1" conaffinity="1" /><geom type="sphere" size="0.000015" pos="0.0 -0.00017984541479043915 0.00049" rgba="1 0.3 0.3 1" mass="0.00041269841269841274" contype="1" conaffinity="1" /><geom type="sphere" size="0.000015" pos="0.0 -1.4999999999999823e-06 0.0" rgba="1 0.3 0.3 1" mass="0.00041269841269841274" contype="1" conaffinity="1" /><geom type="sphere" size="0.000015" pos="0.0 -2.9999999999984466e-08 -4.9e-06" rgba="1 0.3 0.3 1" mass="0.00041269841269841274" contype="1" conaffinity="1" /><geom type="sphere" size="0.000015" pos="0.0 3.0000000000000004e-08 -4.9e-06" rgba="1 0.3 0.3 1" mass="0.00041269841269841274" contype="1" conaffinity="1" /><geom type="sphere" size="0.000015" pos="0.0 1.5e-06 0.0" rgba="1 0.3 0.3 1" mass="0.00041269841269841274" contype="1" conaffinity="1" /><geom type="sphere" size="0.000015" pos="0.0 0.00017984541479043915 0.00049" rgba="1 0.3 0.3 1" mass="0.00041269841269841274" contype="1" conaffinity="1" /><geom type="sphere" size="0.000015" pos="0.0 0.0001828454147904391 0.00049" rgba="1 0.3 0.3 1" mass="0.00041269841269841274" contype="1" conaffinity="1" /><geom type="sphere" size="0.000015" pos="0.0 0.0003611908295808783 0.0" rgba="1 0.3 0.3 1" mass="0.00041269841269841274" contype="1" conaffinity="1" /><geom type="sphere" size="0.000015" pos="0.0 0.0003626608295808783 -4.9e-06" rgba="1 0.3 0.3 1" mass="0.00041269841269841274" contype="1" conaffinity="1" /><geom type="sphere" size="0.000015" pos="0.0 0.00036272082958087825 -4.9e-06" rgba="1 0.3 0.3 1" mass="0.00041269841269841274" contype="1" conaffinity="1" /><geom type="sphere" size="0.000015" pos="0.0 0.00036419082958087824 0.0" rgba="1 0.3 0.3 1" mass="0.00041269841269841274" contype="1" conaffinity="1" /><geom type="sphere" size="0.000015" pos="0.0 0.0005425362443713174 0.00049" rgba="1 0.3 0.3 1" mass="0.00041269841269841274" contype="1" conaffinity="1" /><geom type="sphere" size="0.000015" pos="0.0 0.0005455362443713173 0.00049" rgba="1 0.3 0.3 1" mass="0.00041269841269841274" contype="1" conaffinity="1" /><geom type="sphere" size="0.000015" pos="0.0 0.0007238816591617565 0.0" rgba="1 0.3 0.3 1" mass="0.00041269841269841274" contype="1" conaffinity="1" /><geom type="sphere" size="0.000015" pos="0.0 0.0007253516591617566 -4.9e-06" rgba="1 0.3 0.3 1" mass="0.00041269841269841274" contype="1" conaffinity="1" /><geom type="sphere" size="0.000015" pos="0.0 0.0007254116591617566 -4.9e-06" rgba="1 0.3 0.3 1" mass="0.00041269841269841274" contype="1" conaffinity="1" /><geom type="sphere" size="0.000015" pos="0.0 0.0007268816591617565 0.0" rgba="1 0.3 0.3 1" mass="0.00041269841269841274" contype="1" conaffinity="1" /><geom type="sphere" size="0.000015" pos="0.0 0.0009052270739521957 0.00049" rgba="1 0.3 0.3 1" mass="0.00041269841269841274" contype="1" conaffinity="1" /><geom type="sphere" size="0.000015" pos="0.0 0.0009082270739521957 0.00049" rgba="1 0.3 0.3 1" mass="0.00041269841269841274" contype="1" conaffinity="1" /><geom type="sphere" size="0.000015" pos="0.0 0.0010865724887426347 0.0" rgba="1 0.3 0.3 1" mass="0.00041269841269841274" contype="1" conaffinity="1" /><geom type="sphere" size="0.000015" pos="0.0 0.001088042488742635 -4.9e-06" rgba="1 0.3 0.3 1" mass="0.00041269841269841274" contype="1" conaffinity="1" /><geom type="sphere" size="0.000015" pos="0.0 0.0010881024887426348 -4.9e-06" rgba="1 0.3 0.3 1" mass="0.00041269841269841274" contype="1" conaffinity="1" /><geom type="sphere" size="0.000015" pos="0.0 0.0010895724887426347 0.0" rgba="1 0.3 0.3 1" mass="0.00041269841269841274" contype="1" conaffinity="1" /><geom type="sphere" size="0.000015" pos="0.0 0.0012679179035330738 0.00049" rgba="1 0.3 0.3 1" mass="0.00041269841269841274" contype="1" conaffinity="1" /><geom type="sphere" size="0.000015" pos="0.0 0.0012709179035330738 0.00049" rgba="1 0.3 0.3 1" mass="0.00041269841269841274" contype="1" conaffinity="1" /><geom type="sphere" size="0.000015" pos="0.0 0.001449263318323513 0.0" rgba="1 0.3 0.3 1" mass="0.00041269841269841274" contype="1" conaffinity="1" /><geom type="sphere" size="0.000015" pos="0.0 0.001450733318323513 -4.9e-06" rgba="1 0.3 0.3 1" mass="0.00041269841269841274" contype="1" conaffinity="1" /><geom type="sphere" size="0.000015" pos="0.0 0.001450793318323513 -4.9e-06" rgba="1 0.3 0.3 1" mass="0.00041269841269841274" contype="1" conaffinity="1" /><geom type="sphere" size="0.000015" pos="0.0 0.001452263318323513 0.0" rgba="1 0.3 0.3 1" mass="0.00041269841269841274" contype="1" conaffinity="1" /><geom type="sphere" size="0.000015" pos="0.0 0.0016306087331139521 0.00049" rgba="1 0.3 0.3 1" mass="0.00041269841269841274" contype="1" conaffinity="1" /><geom type="sphere" size="0.000015" pos="0.0 0.001633608733113952 0.00049" rgba="1 0.3 0.3 1" mass="0.00041269841269841274" contype="1" conaffinity="1" /><geom type="sphere" size="0.000015" pos="0.0 0.0018119541479043914 0.0" rgba="1 0.3 0.3 1" mass="0.00041269841269841274" contype="1" conaffinity="1" /><geom type="sphere" size="0.000015" pos="0.0 0.0018134241479043913 -4.9e-06" rgba="1 0.3 0.3 1" mass="0.00041269841269841274" contype="1" conaffinity="1" /><geom type="sphere" size="0.000015" pos="0.0 0.0018134841479043914 -4.9e-06" rgba="1 0.3 0.3 1" mass="0.00041269841269841274" contype="1" conaffinity="1" /><geom type="sphere" size="0.000015" pos="0.0 0.0018149541479043913 0.0" rgba="1 0.3 0.3 1" mass="0.00041269841269841274" contype="1" conaffinity="1" /><geom type="sphere" size="0.000015" pos="0.0 0.0019932995626948304 0.00049" rgba="1 0.3 0.3 1" mass="0.00041269841269841274" contype="1" conaffinity="1" /><geom type="sphere" size="0.000015" pos="0.0 0.0019962995626948304 0.00049" rgba="1 0.3 0.3 1" mass="0.00041269841269841274" contype="1" conaffinity="1" /><geom type="sphere" size="0.000015" pos="0.0 0.0021746449774852697 0.0" rgba="1 0.3 0.3 1" mass="0.00041269841269841274" contype="1" conaffinity="1" /><geom type="sphere" size="0.000015" pos="0.0 0.0021761149774852696 -4.9e-06" rgba="1 0.3 0.3 1" mass="0.00041269841269841274" contype="1" conaffinity="1" /><geom type="sphere" size="0.000015" pos="0.0 0.0021761749774852693 -4.9e-06" rgba="1 0.3 0.3 1" mass="0.00041269841269841274" contype="1" conaffinity="1" /><geom type="sphere" size="0.000015" pos="0.0 0.0021776449774852697 0.0" rgba="1 0.3 0.3 1" mass="0.00041269841269841274" contype="1" conaffinity="1" /><geom type="sphere" size="0.000015" pos="0.0 0.0023559903922757085 0.00049" rgba="1 0.3 0.3 1" mass="0.00041269841269841274" contype="1" conaffinity="1" /><geom type="sphere" size="0.000015" pos="0.0 0.0023589903922757085 0.00049" rgba="1 0.3 0.3 1" mass="0.00041269841269841274" contype="1" conaffinity="1" /><geom type="sphere" size="0.000015" pos="0.0 0.002537335807066148 0.0" rgba="1 0.3 0.3 1" mass="0.00041269841269841274" contype="1" conaffinity="1" /><geom type="sphere" size="0.000015" pos="0.0 0.0025388058070661477 -4.9e-06" rgba="1 0.3 0.3 1" mass="0.00041269841269841274" contype="1" conaffinity="1" /><geom type="sphere" size="0.000015" pos="0.0 0.002538865807066148 -4.9e-06" rgba="1 0.3 0.3 1" mass="0.00041269841269841274" contype="1" conaffinity="1" /><geom type="sphere" size="0.000015" pos="0.0 0.002540335807066148 0.0" rgba="1 0.3 0.3 1" mass="0.00041269841269841274" contype="1" conaffinity="1" /><geom type="sphere" size="0.000015" pos="0.0 0.002718681221856587 0.00049" rgba="1 0.3 0.3 1" mass="0.00041269841269841274" contype="1" conaffinity="1" /><geom type="sphere" size="0.000015" pos="0.0 0.002721681221856587 0.00049" rgba="1 0.3 0.3 1" mass="0.00041269841269841274" contype="1" conaffinity="1" /><geom type="sphere" size="0.000015" pos="0.0 0.0029000266366470263 0.0" rgba="1 0.3 0.3 1" mass="0.00041269841269841274" contype="1" conaffinity="1" /><geom type="sphere" size="0.000015" pos="0.0 0.0029014966366470263 -4.9e-06" rgba="1 0.3 0.3 1" mass="0.00041269841269841274" contype="1" conaffinity="1" /><geom type="sphere" size="0.000015" pos="0.0 0.002901556636647026 -4.9e-06" rgba="1 0.3 0.3 1" mass="0.00041269841269841274" contype="1" conaffinity="1" /><geom type="sphere" size="0.000015" pos="0.0 0.0029030266366470263 0.0" rgba="1 0.3 0.3 1" mass="0.00041269841269841274" contype="1" conaffinity="1" /><geom type="sphere" size="0.000015" pos="0.0 0.003081372051437465 0.00049" rgba="1 0.3 0.3 1" mass="0.00041269841269841274" contype="1" conaffinity="1" /><geom type="sphere" size="0.000015" pos="0.0 0.003084372051437465 0.00049" rgba="1 0.3 0.3 1" mass="0.00041269841269841274" contype="1" conaffinity="1" /><geom type="sphere" size="0.000015" pos="0.0 0.0032627174662279044 0.0" rgba="1 0.3 0.3 1" mass="0.00041269841269841274" contype="1" conaffinity="1" /><geom type="sphere" size="0.000015" pos="0.0 0.0032641874662279044 -4.9e-06" rgba="1 0.3 0.3 1" mass="0.00041269841269841274" contype="1" conaffinity="1" /><geom type="sphere" size="0.000015" pos="0.0 0.003264247466227904 -4.9e-06" rgba="1 0.3 0.3 1" mass="0.00041269841269841274" contype="1" conaffinity="1" /><geom type="sphere" size="0.000015" pos="0.0 0.0032657174662279044 0.0" rgba="1 0.3 0.3 1" mass="0.00041269841269841274" contype="1" conaffinity="1" /><geom type="sphere" size="0.000015" pos="0.0 0.0034440628810183433 0.00049" rgba="1 0.3 0.3 1" mass="0.00041269841269841274" contype="1" conaffinity="1" /><geom type="sphere" size="0.000015" pos="0.0 0.0034470628810183432 0.00049" rgba="1 0.3 0.3 1" mass="0.00041269841269841274" contype="1" conaffinity="1" /><geom type="sphere" size="0.000015" pos="0.0 0.0036254082958087825 0.0" rgba="1 0.3 0.3 1" mass="0.00041269841269841274" contype="1" conaffinity="1" /><geom type="sphere" size="0.000015" pos="0.0 0.0036268782958087825 -4.9e-06" rgba="1 0.3 0.3 1" mass="0.00041269841269841274" contype="1" conaffinity="1" /></body><body name="tooth_plate_0" pos="0 0.0005440362443713174 0.00098" axisangle="0 1 0 180"><geom type="mesh" mesh="tooth_plate_mesh" size="1 1 1" contype="1" conaffinity="1" rgba="0 1 0 1" mass="0.00022" /><joint name="tooth_slider_0" type="slide" axis="0 0 1" stiffness="340.0" springref="-0.01" solimplimit="0.95 0.9999 0.001 0.1 2" solreflimit="0.000075 0.100" limited="true" range="-3.675e-05 1" frictionloss="2.5" solimpfriction="0.95 0.9999 0.001 0.1 2" solreffriction="0.000075 0.030" /></body><body name="tooth_plate_1" pos="0 0.0013600906109282936 0.00098" axisangle="0 1 0 180"><geom type="mesh" mesh="tooth_plate_mesh" size="1 1 1" contype="1" conaffinity="1" rgba="0 1 0 1" mass="0.00022" /><joint name="tooth_slider_1" type="slide" axis="0 0 1" stiffness="340.0" springref="-0.01" solimplimit="0.95 0.9999 0.001 0.1 2" solreflimit="0.000075 0.100" limited="true" range="-3.675e-05 1" frictionloss="2.5" solimpfriction="0.95 0.9999 0.001 0.1 2" solreffriction="0.000075 0.030" /></body><body name="tooth_plate_2" pos="0 0.0021761449774852695 0.00098" axisangle="0 1 0 180"><geom type="mesh" mesh="tooth_plate_mesh" size="1 1 1" contype="1" conaffinity="1" rgba="0 1 0 1" mass="0.00022" /><joint name="tooth_slider_2" type="slide" axis="0 0 1" stiffness="340.0" springref="-0.01" solimplimit="0.95 0.9999 0.001 0.1 2" solreflimit="0.000075 0.100" limited="true" range="-3.675e-05 1" frictionloss="2.5" solimpfriction="0.95 0.9999 0.001 0.1 2" solreffriction="0.000075 0.030" /></body><body name="tooth_plate_3" pos="0 0.0029921993440422453 0.00098" axisangle="0 1 0 180"><geom type="mesh" mesh="tooth_plate_mesh" size="1 1 1" contype="1" conaffinity="1" rgba="0 1 0 1" mass="0.00022" /><joint name="tooth_slider_3" type="slide" axis="0 0 1" stiffness="340.0" springref="-0.01" solimplimit="0.95 0.9999 0.001 0.1 2" solreflimit="0.000075 0.100" limited="true" range="-3.675e-05 1" frictionloss="2.5" solimpfriction="0.95 0.9999 0.001 0.1 2" solreffriction="0.000075 0.030" /></body><camera name="custom_cam2" fovy="0.01" pos="12 0.002 0.0005" quat="0.5 0.5 0.5 0.5" /><camera name="custom_cam3" pos="0.0025 0.0015 0.0005" quat="0.5 0.5 0.5 0.5" /><camera name="custom_cam4" pos="0.005 0.0004 0" quat="0.5 0.5 0.5 0.5" /></worldbody><actuator><general joint="rack_slider" name="rack_actuator" gainprm="1" /><general joint="tooth_slider_0" name="tooth_slider_actuator_0" gainprm="1" /><general joint="tooth_slider_1" name="tooth_slider_actuator_1" gainprm="1" /><general joint="tooth_slider_2" name="tooth_slider_actuator_2" gainprm="1" /><general joint="tooth_slider_3" name="tooth_slider_actuator_3" gainprm="1" /></actuator><option timestep="2e-06" gravity="0 0 0" /><default><geom solimp="0.95 0.9999 0.001 0.1 2" solref="0.000075 0.030" margin="0.00000001" /></default><compiler /><visual><global offwidth="800" offheight="600" /><map znear="0.0000001" zfar="100000" /></visual></mujoco>